Workbook

Sheet Hypotheses
A1: Hypotheses du modele de rentabilite — App anniversaire & cadeaux (Pensif)
A2: Cellules en bleu = a ajuster librement. Cellules en noir = calculees automatiquement.
A4: Parametre | B4: Valeur | C4: Unite | D4: Source / justification
A5: Contacts suivis par utilisateur actif (moyenne) | B5: 8 | C5: contacts | D5: Hypothese produit a valider par tests utilisateurs (repertoire d'anniversaires suivis)
A6: Panier moyen du cadeau achete via l'app | B6: 40 | C6: EUR | D6: Estime a partir des budgets anniversaire ami proche / famille proche (25-50 EUR) — voir onglet 'Programmes affiliation', tableau budgets
A7: Part des achats via catalogue generaliste (Amazon / Cdiscount) | B7: 0.6 | D7: Hypothese de repartition — a affiner avec des donnees d'usage reelles
A8: Part des achats via fleuriste / chocolatier (envoi jour J) | B8: =1-B7 -> 0.4 | D8: Calcule automatiquement : 1 - part generaliste
A9: Commission moyenne generaliste (blend Amazon ~3-4% / Cdiscount 2-8% selon categorie) | B9: 0.04 | D9: Amazon Partenaires: jusqu'a 12% annonce mais barreme reel par categorie non public en detail, la plupart des categories cadeaux ~3-4% (lafabriquedunet.fr). Cdiscount via Awin: jusqu'a 6-8%, ex. mode 4-5%, maison 2.5-3.5%, high-tech 2-3% (freudix.studio, ui.awin.com)
A10: Commission moyenne fleuriste / chocolatier (blend, ex. Interflora) | B10: 0.06 | D10: Interflora via TimeOne: CPA ~9% (cashback) / 4,5% sur gamme petit prix (performance.timeonegroup.com). Euroflorist (Tradedoubler) et 123fleurs: taux non publies, sur candidature — retenu 6% par prudence
A11: Commission moyenne ponderee (generaliste + fleuriste) | B11: =B7*B9+B8*B10 -> 0.048 | D11: Calcule automatiquement : part generaliste x commission generaliste + part fleuriste x commission fleuriste
A12: Taux de conversion — scenario pessimiste | B12: 0.05 | D12: % des rappels d'anniversaire qui debouchent sur un achat via un lien affilie de l'app. Non valide par des donnees reelles — a mesurer des le MVP
A13: Taux de conversion — scenario median | B13: 0.1 | D13: Idem, hypothese mediane
A14: Taux de conversion — scenario optimiste | B14: 0.18 | D14: Idem, hypothese haute (audience tres qualifiee / forte pertinence du matching)
A16: Couts du projet — poste par poste (chiffres fournis par l'utilisateur + recherche sourcee)
A17: Poste | B17: Type | C17: Montant (EUR) | D17: Source / note
A18: Hebergement backend — Supabase, plan Pro | B18: Annuel | C18: 276 | D18: 25 USD/mois x 12, conversion approx. ~0,92 EUR/USD (nocode.mba, article Supabase Pricing 2026). Quota inclus jusqu'a 100 000 utilisateurs actifs/mois — largement suffisant a ce stade
A19: Compte developpeur Apple (App Store) | B19: Annuel | C19: 91 | D19: 99 USD/an (confirme par l'utilisateur), conversion approx. ~0,92 EUR/USD. Necessaire uniquement a partir de la publication sur iOS
A20: Compte developpeur Google Play | B20: Unique | C20: 23 | D20: 25 USD, paiement unique (confirme par l'utilisateur) — pas un cout annuel
A21: Depot de marque INPI (1 classe) | B21: Unique | C21: 190 | D21: Tarif officiel INPI 2026 pour une classe, depot en ligne (legalplace.fr) — proche de l'estimation de l'utilisateur (200 EUR). Uniquement si le projet va au bout
A22: Nom de domaine | B22: Annuel | C22: 0 | D22: Non prevu pour le moment (pas de site prevu). Si ajoute plus tard : ~10-15 EUR/an pour un nom de domaine seul, ou davantage si couple a un abonnement site (type Wix/Squarespace, ~12 EUR/mois) — a clarifier selon ce qui est vise
A23: Abonnement Claude (usage dev personnel, Claude Code) | B23: Annuel | C23: 0 | D23: 21,60 EUR/mois deja paye par l'utilisateur, mutualise avec ses autres projets — cout marginal nul attribuable a ce projet. Attention : distinct de l'API de production utilisee par l'app (voir cout variable ci-dessous)
A24: Couts additionnels optionnels (ex: aide freelance ponctuelle) — mettre 0 si aucun | B24: Annuel | C24: 0 | D24: A ajuster librement si vous prevoyez de sous-traiter une partie du developpement ou du design
A25: TOTAL couts fixes ANNUELS (recurrents) | C25: =SUMIF(B18:B24,"Annuel",C18:C24) -> 367 | D25: Somme des postes marques 'Annuel' ci-dessus
A26: TOTAL couts UNIQUES (lancement, hors annees suivantes) | C26: =SUMIF(B18:B24,"Unique",C18:C24) -> 213 | D26: Somme des postes marques 'Unique' ci-dessus — a prevoir la 1ere annee seulement
A28: Cout variable — API LLM de production (par utilisateur actif / an)
A29: Cout API LLM de production par utilisateur actif / an | C29: 0.04 | D29: Base de calcul : Claude Haiku (modele economique) = 1 USD/M tokens en entree, 5 USD/M en sortie (benchlm.ai, aout 2026). Hypothese ~16 appels/utilisateur/an (8 contacts x 1 interpretation initiale des 3 reponses + 1 rafraichissement annuel de la recommandation), ~1000 tokens entree / 300 tokens sortie par appel -> ~0,04 EUR/utilisateur/an. C'est une API de production facturee a l'usage, distincte de l'abonnement Claude personnel utilise pour coder. A recalibrer avec la consommation reelle du MVP

Sheet Programmes affiliation
A1: Recherche — programmes d'affiliation identifies (aout 2026)
A2: A confirmer directement aupres de chaque programme avant integration (taux exacts non toujours publics)
A4: Programme | B4: Plateforme | C4: Commission indiquee | D4: Cookie | E4: Inscription | F4: Source
A5: Amazon Partenaires (Amazon.fr) | B5: Directe (Amazon Associates) | C5: Jusqu'a 12% annonce ; barreme detaille par categorie non public — la plupart des categories cadeaux (maison, jouets, mode, beaute) ~3-4% par recoupement | D5: Non confirme (a verifier sur la console partenaire) | E5: Libre, gratuite, sans frais | F5: lafabriquedunet.fr/logiciel/amazon-partenaires
A6: Cdiscount | B6: Awin | C6: Jusqu'a 6-8% selon categorie : high-tech ~2-3%, maison ~2.5-3.5%, loisirs ~3-4%, mode ~4-5% | D6: 7 jours | E6: Candidature via Awin (validation requise) ; paiement min. 20 EUR, mensuel/bimensuel | F6: freudix.studio/programmes-affiliation/cdiscount ; ui.awin.com/merchant-profile/6948
A7: Interflora | B7: TimeOne | C7: CPA ~9% (cashback) / 4,5% sur gamme 'petit prix' ; 8 EUR forfait sur segment deuil (non pertinent ici) | D7: Non precise | E7: Contact direct : interflora@timeonegroup.com | F7: interflora.fr/affiliation ; performance.timeonegroup.com
A8: Euroflorist / Telefleurs | B8: Tradedoubler | C8: Non publie — 'free & easy to apply' | D8: Non precise | E8: Candidature sur Tradedoubler | F8: euroflorist.fr/en/programme-daffiliation-cn935 ; directory.tradedoubler.com
A9: 123fleurs | B9: Programme propre (direct) | C9: Non publie — sur demande | D9: Non precise | E9: Contact service affiliation : 03 79 33 67 09 | F9: 123fleurs.com/infos/affiliation
A10: Chocolatiers (Leonidas, Jeff de Bruges, etc.) | B10: Aucun programme structure identifie en libre-service | C10: N/A | D10: N/A | E10: Probablement prise de contact directe, ou via un reseau generaliste (Awin / TimeOne / Effinity) | F10: Recherche web aout 2026 — aucun programme dedie trouve
A12: Budgets cadeau anniversaire observes en France (pour calibrer le panier moyen)
A13: Lien avec la personne | B13: Budget observe | F13: Source
A14: Ami proche | B14: ~50 EUR | F14: profitrama.com/budget-cadeau-anniversaire
A15: Famille proche (parents, fratrie) | B15: 50-150 EUR | F15: poupala.fr/quel-montant-pour-un-anniversaire
A16: Connaissance | B16: ~20 EUR | F16: profitrama.com/budget-cadeau-anniversaire
A17: Collegue (cagnotte collective) | B17: 10-20 EUR | F17: poupala.fr ; profitrama.com
A18: Moyenne globale tous liens confondus | B18: ~35 EUR | F18: poupala.fr/quel-montant-pour-un-anniversaire
A19: Anniversaires marquants (18, 30, 50 ans) | B19: x2 le budget habituel | F19: profitrama.com/budget-cadeau-anniversaire

Sheet Modele de rentabilite
A1: Modele de rentabilite — revenu d'affiliation
A2: Revenu par utilisateur actif/an = contacts suivis x taux de conversion x panier moyen x commission ponderee (voir onglet Hypotheses)
B4: Pessimiste | C4: Median | D4: Optimiste
A5: Taux de conversion retenu | B5: =Hypotheses!B12 -> 0.05 | C5: =Hypotheses!B13 -> 0.1 | D5: =Hypotheses!B14 -> 0.18
A6: Revenu d'affiliation par utilisateur actif / an (EUR) | B6: =Hypotheses!$B$5*B5*Hypotheses!$B$6*Hypotheses!$B$11 -> 0.768 | C6: =Hypotheses!$B$5*C5*Hypotheses!$B$6*Hypotheses!$B$11 -> 1.536 | D6: =Hypotheses!$B$5*D5*Hypotheses!$B$6*Hypotheses!$B$11 -> 2.7648
A7: Cout variable API LLM production par utilisateur actif / an (EUR) | B7: =Hypotheses!$C$29 -> 0.04 | C7: =Hypotheses!$C$29 -> 0.04 | D7: =Hypotheses!$C$29 -> 0.04
A8: Marge nette par utilisateur actif / an (EUR) | B8: =B6-B7 -> 0.728 | C8: =C6-C7 -> 1.496 | D8: =D6-D7 -> 2.7248
A11: Profit net annuel selon la base d'utilisateurs actifs (marge nette x utilisateurs - couts fixes)
A12: Utilisateurs actifs (MAU) | B12: Pessimiste | C12: Median | D12: Optimiste
A13: 500 | B13: =$A13*B$8-Hypotheses!$C$25 -> -3 | C13: =$A13*C$8-Hypotheses!$C$25 -> 381 | D13: =$A13*D$8-Hypotheses!$C$25 -> 995.4
A14: 1000 | B14: =$A14*B$8-Hypotheses!$C$25 -> 361 | C14: =$A14*C$8-Hypotheses!$C$25 -> 1129 | D14: =$A14*D$8-Hypotheses!$C$25 -> 2357.8
A15: 5000 | B15: =$A15*B$8-Hypotheses!$C$25 -> 3273 | C15: =$A15*C$8-Hypotheses!$C$25 -> 7113 | D15: =$A15*D$8-Hypotheses!$C$25 -> 13257
A16: 10000 | B16: =$A16*B$8-Hypotheses!$C$25 -> 6913 | C16: =$A16*C$8-Hypotheses!$C$25 -> 14593 | D16: =$A16*D$8-Hypotheses!$C$25 -> 26881
A17: 50000 | B17: =$A17*B$8-Hypotheses!$C$25 -> 36033 | C17: =$A17*C$8-Hypotheses!$C$25 -> 74433 | D17: =$A17*D$8-Hypotheses!$C$25 -> 135873
A18: 100000 | B18: =$A18*B$8-Hypotheses!$C$25 -> 72433 | C18: =$A18*C$8-Hypotheses!$C$25 -> 149233 | D18: =$A18*D$8-Hypotheses!$C$25 -> 272113
A21: Utilisateurs actifs necessaires pour atteindre le seuil de rentabilite (couts annuels recurrents uniquement — hors couts de lancement uniques)
B22: Pessimiste | C22: Median | D22: Optimiste
A23: Couts fixes annuels recurrents seuls | B23: =Hypotheses!$C$25/B$8 -> 504.12088 | C23: =Hypotheses!$C$25/C$8 -> 245.32086 | D23: =Hypotheses!$C$25/D$8 -> 134.68878
A24: Annee 1 (couts annuels recurrents + couts uniques de lancement) | B24: =(Hypotheses!$C$25+Hypotheses!$C$26)/B$8 -> 796.7033 | C24: =(Hypotheses!$C$25+Hypotheses!$C$26)/C$8 -> 387.70053 | D24: =(Hypotheses!$C$25+Hypotheses!$C$26)/D$8 -> 212.85966
A26: Lecture : avec des couts fixes annuels recurrents tres bas (Supabase + compte developpeur Apple, hors couts de lancement uniques comme le depot de marque ou le compte Google Play), le seuil de rentabilite est atteint des quelques dizaines a quelques centaines d'utilisateurs actifs selon le scenario. Les couts uniques de lancement (voir onglet Hypotheses, ligne 'TOTAL couts UNIQUES') sont a couvrir une seule fois, la 1ere annee. Ces volumes sont des utilisateurs ACTIFS (suivent des contacts et achetent via l'app), pas des installations.

Sheet Sensibilite
A1: Sensibilite du profit — quel levier pese le plus ?
A2: Chaque tableau fait varier UN SEUL parametre (les autres restent a leur valeur mediane) pour isoler son effet sur le profit annuel, a base d'utilisateurs actifs fixe.
A4: Utilisateurs actifs de reference pour cette analyse | B4: 10000
A6: 1. Taux de conversion rappel -> achat (1% a 25%)
A7: Fourchette la plus large : c'est la seule variable sans aucune donnee reelle (le produit n'existe pas encore). Benchmarks affiliation generalistes : 1-3% en moyenne, 5-10% pour du contenu tres pertinent (wecantrack.com).
A8: Valeur testee | B8: Profit annuel (EUR)
A9: 0.01 | B9: =$B$4*(Hypotheses!$B$5*A9*Hypotheses!$B$6*Hypotheses!$B$11-Hypotheses!$C$29)-Hypotheses!$C$25 -> 769
A10: 0.02 | B10: =$B$4*(Hypotheses!$B$5*A10*Hypotheses!$B$6*Hypotheses!$B$11-Hypotheses!$C$29)-Hypotheses!$C$25 -> 2305
A11: 0.05 | B11: =$B$4*(Hypotheses!$B$5*A11*Hypotheses!$B$6*Hypotheses!$B$11-Hypotheses!$C$29)-Hypotheses!$C$25 -> 6913
A12: 0.08 | B12: =$B$4*(Hypotheses!$B$5*A12*Hypotheses!$B$6*Hypotheses!$B$11-Hypotheses!$C$29)-Hypotheses!$C$25 -> 11521
A13: 0.1 | B13: =$B$4*(Hypotheses!$B$5*A13*Hypotheses!$B$6*Hypotheses!$B$11-Hypotheses!$C$29)-Hypotheses!$C$25 -> 14593
A14: 0.15 | B14: =$B$4*(Hypotheses!$B$5*A14*Hypotheses!$B$6*Hypotheses!$B$11-Hypotheses!$C$29)-Hypotheses!$C$25 -> 22273
A15: 0.18 | B15: =$B$4*(Hypotheses!$B$5*A15*Hypotheses!$B$6*Hypotheses!$B$11-Hypotheses!$C$29)-Hypotheses!$C$25 -> 26881
A16: 0.25 | B16: =$B$4*(Hypotheses!$B$5*A16*Hypotheses!$B$6*Hypotheses!$B$11-Hypotheses!$C$29)-Hypotheses!$C$25 -> 37633
A17: Ecart (max - min) | B17: =MAX(B9:B16)-MIN(B9:B16) -> 36864
A19: 2. Commission moyenne ponderee (2% a 9%)
A20: Fourchette bornee par les programmes reellement identifies (onglet 'Programmes affiliation') : de Cdiscount high-tech (~2-3%) a Interflora cashback (~9%). Levier peu controlable : fixe par les programmes, pas par le produit.
A21: Valeur testee | B21: Profit annuel (EUR)
A22: 0.02 | B22: =$B$4*(Hypotheses!$B$5*Hypotheses!$B$13*Hypotheses!$B$6*A22-Hypotheses!$C$29)-Hypotheses!$C$25 -> 5633
A23: 0.04 | B23: =$B$4*(Hypotheses!$B$5*Hypotheses!$B$13*Hypotheses!$B$6*A23-Hypotheses!$C$29)-Hypotheses!$C$25 -> 12033
A24: 0.048 | B24: =$B$4*(Hypotheses!$B$5*Hypotheses!$B$13*Hypotheses!$B$6*A24-Hypotheses!$C$29)-Hypotheses!$C$25 -> 14593
A25: 0.06 | B25: =$B$4*(Hypotheses!$B$5*Hypotheses!$B$13*Hypotheses!$B$6*A25-Hypotheses!$C$29)-Hypotheses!$C$25 -> 18433
A26: 0.08 | B26: =$B$4*(Hypotheses!$B$5*Hypotheses!$B$13*Hypotheses!$B$6*A26-Hypotheses!$C$29)-Hypotheses!$C$25 -> 24833
A27: 0.09 | B27: =$B$4*(Hypotheses!$B$5*Hypotheses!$B$13*Hypotheses!$B$6*A27-Hypotheses!$C$29)-Hypotheses!$C$25 -> 28033
A28: Ecart (max - min) | B28: =MAX(B22:B27)-MIN(B22:B27) -> 22400
A30: 3. Panier moyen (20 EUR a 100 EUR)
A31: Fourchette calibree sur les budgets anniversaire observes (onglet 'Programmes affiliation') : de la connaissance (~20 EUR) aux anniversaires marquants en famille proche (jusqu'a 100+ EUR). Peu controlable par le produit (norme sociale).
A32: Valeur testee | B32: Profit annuel (EUR)
A33: 20 | B33: =$B$4*(Hypotheses!$B$5*Hypotheses!$B$13*A33*Hypotheses!$B$11-Hypotheses!$C$29)-Hypotheses!$C$25 -> 6913
A34: 30 | B34: =$B$4*(Hypotheses!$B$5*Hypotheses!$B$13*A34*Hypotheses!$B$11-Hypotheses!$C$29)-Hypotheses!$C$25 -> 10753
A35: 40 | B35: =$B$4*(Hypotheses!$B$5*Hypotheses!$B$13*A35*Hypotheses!$B$11-Hypotheses!$C$29)-Hypotheses!$C$25 -> 14593
A36: 50 | B36: =$B$4*(Hypotheses!$B$5*Hypotheses!$B$13*A36*Hypotheses!$B$11-Hypotheses!$C$29)-Hypotheses!$C$25 -> 18433
A37: 60 | B37: =$B$4*(Hypotheses!$B$5*Hypotheses!$B$13*A37*Hypotheses!$B$11-Hypotheses!$C$29)-Hypotheses!$C$25 -> 22273
A38: 80 | B38: =$B$4*(Hypotheses!$B$5*Hypotheses!$B$13*A38*Hypotheses!$B$11-Hypotheses!$C$29)-Hypotheses!$C$25 -> 29953
A39: 100 | B39: =$B$4*(Hypotheses!$B$5*Hypotheses!$B$13*A39*Hypotheses!$B$11-Hypotheses!$C$29)-Hypotheses!$C$25 -> 37633
A40: Ecart (max - min) | B40: =MAX(B33:B39)-MIN(B33:B39) -> 30720
A42: 4. Contacts suivis par utilisateur actif (4 a 15)
A43: Levier partiellement controlable via l'onboarding (encourager a ajouter plus de contacts). Fourchette raisonnable pour un usage regulier.
A44: Valeur testee | B44: Profit annuel (EUR)
A45: 4 | B45: =$B$4*(A45*Hypotheses!$B$13*Hypotheses!$B$6*Hypotheses!$B$11-Hypotheses!$C$29)-Hypotheses!$C$25 -> 6913
...
